Workbook

Sheet Operaciones
B2: 2024 | C2: Accidentología (N° accidente/millon de hs trabajadas)
C3: ENE | D3: FEB | E3: MAR | F3: ABR | G3: MAY | H3: JUN | I3: JUL | J3: AGO | K3: SEP | L3: OCT | M3: NOV | N3: DIC
B4: Comirsa
B5: Represa
B6: Chapa
B7: Gasoducto
B8: Rio Turbio
B9: POBA
B10: San Luis
B11: Rincón
B12: Chavez
B13: CABA
B14: Añelo
B15: Vicente Lopez
... B17: Blanca Luna

Sheet Evolución
C3: CABA | D3: POBA | E3: UBA | F3: Bahía Blanca | G3: Comirsa | H3: Olavarría | I3: Rio Colorado | J3: Añelo | K3: AESA | L3: Rincon | M3: Córdoba | N3: San Luis | O3: Salta
B4: Dotación Promedio | C4: ='CABA '!B19 -> 0 | D4: ='POBA -25'!B19 -> 24.25 | E4: =UBA!B19 -> 12.083333 | F4: ='Bahia Blanca'!B19 -> 11.416667 | G4: =Comirsa!B19 -> 5 | H4: =Olavarria!B19 -> 0.83333333 | I4: ='Rio Colorado'!B19 -> 0.83333333 | J4: =Añelo!B19 -> 11.083333 | K4: ='AESA (Punta Arena)'!B19 -> 19.333333 | L4: ='Ricon de los Sauces'!B19 -> 41.714286 | M4: ='Cordoba 2024'!B19 -> 5.25 | N4: ='San Luis - Villa Mercedes'!B19 -> 12.25 | O4: =Salta!B19 -> 7.5
B5: Indice de Incidencia | C5: ='CABA '!E22 -> #DIV/0! | D5: ='POBA -25'!E22 -> 82.474227 | E5: =UBA!E22 -> 0 | F5: ='Bahia Blanca'!E22 -> 0 | G5: =Comirsa!E22 -> 0 | H5: =Olavarria!E22 -> 0 | I5: ='Rio Colorado'!E22 -> 0 | J5: =Añelo!E22 -> 0 | K5: ='AESA (Punta Arena)'!E22 -> 0 | L5: ='Ricon de los Sauces'!E22 -> 23.972603 | M5: ='Cordoba 2024'!E22 -> 0 | N5: ='San Luis - Villa Mercedes'!E22 -> 81.632653 | O5: =Salta!E22 -> 133.33333
B6: Indice de Frecuencia | C6: ='CABA '!E25 -> #DIV/0! | D6: ='POBA -25'!E25 -> 34.896706 | E6: =UBA!E25 -> 0 | F6: ='Bahia Blanca'!E25 -> 0 | G6: =Comirsa!E25 -> 0 | H6: =Olavarria!E25 -> 0 | I6: ='Rio Colorado'!E25 -> 0 | J6: =Añelo!E25 -> 0 | K6: ='AESA (Punta Arena)'!E25 -> 0 | L6: ='Ricon de los Sauces'!E25 -> 17.337032 | M6: ='Cordoba 2024'!E25 -> 0 | N6: ='San Luis - Villa Mercedes'!E25 -> 35.114825 | O6: =Salta!E25 -> 57.077626
B7: Indice de Gravedad | C7: ='CABA '!E28 -> #DIV/0! | D7: ='POBA -25'!E28 -> 0.20618557 | E7: =UBA!E28 -> 0 | F7: ='Bahia Blanca'!E28 -> 0 | G7: =Comirsa!E28 -> 0 | H7: =Olavarria!E28 -> 0 | I7: ='Rio Colorado'!E28 -> 0 | J7: =Añelo!E28 -> 0 | K7: ='AESA (Punta Arena)'!E28 -> 0 | L7: ='Ricon de los Sauces'!E28 -> 0.59931507 | M7: ='Cordoba 2024'!E28 -> 0 | N7: ='San Luis - Villa Mercedes'!E28 -> 0.89795918 | O7: =Salta!E28 -> 8.1333333

Sheet CONSOLIDADO
B2: Operación | C2: Mes | D2: Año | E2: Accidentes | F2: Cada cuantos dias se espera un evento
B3: San Nicolás | C3: Enero | D3: 2024 | E3: 0 | F3: Sin eventos registrados
B4: San Nicolás | C4: Febrero | D4: 2024 | E4: 0 | F4: Sin eventos registrados
B5: San Nicolás | C5: Marzo | D5: 2024 | E5: 0 | F5: Sin eventos registrados
B6: San Nicolás | C6: Abril | D6: 2024 | E6: 0 | F6: Sin eventos registrados
B7: San Nicolás | C7: Mayo | D7: 2024 | E7: 0 | F7: Sin eventos registrados
B8: San Nicolás | C8: Junio | D8: 2024 | E8: 0 | F8: Sin eventos registrados
B9: San Nicolás | C9: Julio | D9: 2024 | E9: 0 | F9: Sin eventos registrados
B10: CABA | C10: Enero | D10: 2024 | E10: 0 | F10: Sin eventos registrados
B11: CABA | C11: Febrero | D11: 2024 | E11: 0 | F11: Sin eventos registrados
B12: CABA | C12: Marzo | D12: 2024 | E12: 0 | F12: Sin eventos registrados
B13: CABA | C13: Abril | D13: 2024 | E13: 0 | F13: Sin eventos registrados
B14: CABA | C14: Mayo | D14: 2024 | E14: 0 | F14: Sin eventos registrados
B15: CABA | C15: Junio | D15: 2024 | E15: 0 | F15: 105
B16: CABA | C16: Julio | D16: 2024 | E16: 2 | F16: 120
B17: POBA | C17: Enero | D17: 2024 | E17: 1 | F17: 60
B18: POBA | C18: Febrero | D18: 2024 | E18: 0 | F18: 90
B19: POBA | C19: Marzo | D19: 2024 | E19: 0 | F19: 120
B20: POBA | C20: Abril | D20: 2024 | E20: 0 | F20: 150
B21: POBA | C21: Mayo | D21: 2024 | E21: 0 | F21: 180
B22: POBA | C22: Junio | D22: 2024 | E22: 0 | F22: 210
B23: POBA | C23: Julio | D23: 2024 | E23: 0 | F23: 240
B24: UBA | C24: Enero | D24: 2024 | E24: 0 | F24: Sin eventos registrados
B25: UBA | C25: Febrero | D25: 2024 | E25: 0 | F25: Sin eventos registrados
B26: UBA | C26: Marzo | D26: 2024 | E26: 0 | F26: Sin eventos registrados
B27: UBA | C27: Abril | D27: 2024 | E27: 0 | F27: Sin eventos registrados
B28: UBA | C28: Mayo | D28: 2024 | E28: 0 | F28: Sin eventos registrados
B29: UBA | C29: Junio | D29: 2024 | E29: 0 | F29: Sin eventos registrados
B30: UBA | C30: Julio | D30: 2024 | E30: 0 | F30: Sin eventos registrados
B31: Bahía Blanca | C31: Enero | D31: 2024 | E31: 0 | F31: Sin eventos registrados
B32: Bahía Blanca | C32: Febrero | D32: 2024 | E32: 0 | F32: Sin eventos registrados
B33: Bahía Blanca | C33: Marzo | D33: 2024 | E33: 0 | F33: Sin eventos registrados
B34: Bahía Blanca | C34: Abril | D34: 2024 | E34: 0 | F34: Sin eventos registrados
B35: Bahía Blanca | C35: Mayo | D35: 2024 | E35: 0 | F35: Sin eventos registrados
... B53: Añelo | C53: Febrero | D53: 2024 | E53: 0 | F53: Sin eventos registrados
B54: Añelo | C54: Marzo | D54: 2024 | E54: 0 | F54: 120
B55: Añelo | C55: Abril | D55: 2024 | E55: 1 | F55: 150
B56: Añelo | C56: Mayo | D56: 2024 | E56: 0 | F56: 180
B57: Añelo | C57: Junio | D57: 2024 | E57: 0 | F57: 210
B58: Añelo | C58: Julio | D58: 2024 | E58: 0 | F58: 240
...

Sheet Casos 2023
A2: Apellido y Nombre | B2: operacion | C2: Accidente | D2: Fin ILT | E2: Dias Acc | F2: Tipo de accidente | G2: Cumputa? | H2: 44927 | I2: 44958 | J2: 44986 | K2: 45017 | L2: 45047 | M2: 45078 | N2: 45108 | O2: 45139 | P2: 45170 | Q2: 45200 | R2: 45231 | S2: 45261 | T2: 45292 | U2: 45323 | V2: 45352 | W2: 45383 | X2: 45413 | Y2: 45444 | Z2: 45474 | AA2: 45505 | AB2: 45536 | AC2: 45566 | AD2: 45597 | AE2: 45627 | AF2: 45658 | AG2: 45689 | AH2: 45717 | AI2: 45748 | AJ2: 45778 | AK2: 45809 | AL2: 45839 | AM2: 45870 | AN2: 45901 | AO2: 45931 | AP2: 45962 | AQ2: 45992 | AR2: 46023 | AS2: 46054
A3: SUAREZ MELISA VANINA | B3: chapa | C3: 44937 | D3: 17/01/2023 | E3: 6 | F3: SUFRIÓ UN ESGUINCE EN LA MUÑECA IZQUIERDA | G3: si | H3: x
A4: PALOMINO FEDERICO ALEJANDRO | B4: chapa | C4: 26/01/2023 | D4: 27/01/2023 | E4: 2 | F4: SALPICA AGUA CALIENTE CAYENDO EN ROSTRO Y PIERNA | G4: si | H4: x
A5: AVELLANEDA HECTOR ANIBAL | B5: POBA | C5: 44962 | D5: 09/02/2023 | E5: 5 | F5: ABRIR LA HELADERA SE LE CIERRA LA PIERTA EN LA CARA Y SE GOLPEA OJO DERECHO | G5: si | H5: x
A6: QUINTANA NANCY EDITH | B6: chapa | C6: 11/02/2023 | D6: 13/02/2023 | E6: 2 | F6: REFIERE QUE POR EQUIVOCACION BEBE CERA LIQUIDA | G6: si | I6: x
A7: QUINTANA NANCY EDITH | B7: chapa | C7: 44977 | D7: 22/02/2023 | E7: 2 | F7: REFIERE QUE EN EL TRANSCURSO DEL DIA SE LE INFLAMA EL PIE DCHO ACAUSA DE LAS TAREAS REALIZADAS | G7: si | I7: x
A8: CRUZ NADIA ANAHI BELEN | B8: represa | C8: 25/03/2023 | D8: 19/04/2023 | E8: 23 | F8: E RESBALA Y CAE , GOLPEANDOTE LA CABEZA | G8: si | J8: x | K8: x
A9: ACEVEDO NAHUEL | B9: Gasoducto | C9: 45044 | D9: 11/05/2023 | E9: 14 | F9: BAJANDO UN GARRAFON DE GAS DE UNA DE LAS CAMIONETAS DE LA EMPRESA, SE DESLIZÓ YÉNDOSE AL PISO Y GOLPEANDO LA MANO | G9: si | K9: x | L9: x
A10: PUMALLOCLLA SOLIS NIEVES | B10: turbio | C10: 30/04/2023 | D10: 24/06/2023 | E10: 54 | F10: REF QUE ESTABA SOBRE UNA SILLA LIMPIEANDO UN MICROONDA, LA SILLA SE DIO VUELTA, CAYO DE ESPALDA Y SE GOLPEO EL TALON DERECHO. | G10: si | K10: x | L10: x | M10: x
A11: RAMIREZ ELIZABETH | B11: comirsa | C11: 45055 | D11: 15/05/2023 | E11: 6 | F11: REFIERE QUE AL LEVANTAR UNA PLACA DE HORNO LE AGARRA DOLOR DE HOMBRO IZQUIERDA | G11: si | L11: x
A12: RIVERO YAMILA JULIANA | B12: Gasoducto | C12: 09/05/202 | D12: 29/09/2023 | E12: 144 | F12: ESTABA TRABAJANDO EN UN TRÁILER, QUISO ABRIR LA PUERTA PARA APAGAR LAS LUCES Y SE CERRÓ LA PUERTA APRETÁNDOLE EL DEDO PULGAR DE LA MANO IZQUIERDA, | G12: si | L12: x | M12: x | N12: x | O12: x | P12: x
A13: RODRIGUEZ LUCAS EZEQUIE | B13: cordoba | C13: 11/05/2023 | D13: 18/05/2023 | E13: 3 | F13: TIRON EN LA ZONA LUMBAR | G13: si | L13: x | Q13: x
A14: RODRIGUEZ LUCAS EZEQUIE | B14: cordoba | C14: 09/10/2023 | F14: recaida | G14: si
A15: CUEVAS SARA | B15: chapa | C15: 12/05/2023 | D15: 45184 | E15: 127 | F15: SE ENCONTRABA EN EL BAÑO LIMPIANDO Y SE RESBALA, SE GOLPEA EN LA RODILLA DERECHA, BRAZO DERECHO Y MANO DERECHA | G15: si | L15: x | M15: x | N15: x | O15: x | P15: x
A16: SANCHEZ ELENA BEATRIZ | B16: represa | C16: 01/06/2023 | D16: 25/07/2023 | E16: 44 | F16: SE RESBALA EN EL TRABAJO Y CAE | G16: si | M16: x | N16: x
A17: PONCE VIRGINIA ISABEL | B17: comirsa | C17: 07/06/2023 | D17: 27/06/2023 | E17: 20 | F17: SINTIO UN TIRON EN LA ESPALDA | G17: si | M17: x
A18: RODRIGUEZ MARCIA SABRINA | B18: represa | C18: 45100 | D18: 04/07/2023 | E18: 11 | F18: SE RESBALA Y CAE AL SUELO | G18: si | M18: x
A19: CONTRERA ROMINA ANDREA | B19: represa | C19: 45104 | D19: 18/07/2023 | E19: 20 | F19: SE LE CAE AGUA CALIENTE EN PIE IZQUIERDO | G19: si | M19: x | N19: x
A20: QUINTANA NANCY EDITH | B20: chapa | C20: 14/07/2023 | D20: 30/10/2023 | E20: 109 | F20: ESTABA BAJANDO LAS ESCALERAS, HABIAN ENCERADO Y SE PATINO, | G20: si | O20: x | P20: x | Q20: x | R20: x
A21: AVENIDA SAN MARTIN 200 Loc.LA REJA | B21: bahi blanca | C21: 45130 | D21: 28/07/2023 | E21: 5 | F21: CORTANDO FIAMBRE, LA MAQUINA SE RESBALO Y CUANDO QUISE SUJETARLA HICE MUCHA FUERZA, SENTI UN FUERTE DOLOR EN EL HOMBRO IZQUIERDO | G21: si | N21: x
A22: ACOSTA BRUNO | B22: chapa | C22: 22/09/2023 | D22: 27/09/2023 | E22: 5 | F22: REF QUE ESTABA CARGANDO BATEAS CON ARROS, AL SUBIR UNA ESCALERA COMUN SINTIO UNA PUNTADA EN LA RODILLA IZQ. | G22: si | P22: x
A23: SALAS ROLANDO ANDRES | B23: chapa | C23: 45192 | D23: 02/10/2023 | E23: 9 | F23: REALIZANDO LIMPIEZA DE MESADASE CORTA CON FILO DE LA MISMA EN DEDO PULGAR E INDICE DE MANO IZQUIERDA | G23: si | P23: x | Q23: x
A24: HERNANDEZ GUSTAVO ARIEL | B24: santa cruz | C24: 24/09/2023 | D24: 24/10/2023 | E24: 30 | F24: POR REBALSE DE CLOACAS SE CAE GOLPEANDO ESPALADA, COXIS, CUELLO Y CABEZA CON POSIBLE PERDIDA DE CONOC. RECUPERADA | G24: si | P24: x | Q24: x
A25: ACOSTA BRUNO | B25: chapa | C25: 26/09/2023 | D25: 04/10/2023 | E25: 8 | F25: REFIERE QUE ESTABA TRANSPORTANDO UNA OLLA DE AGUA CALIENTE, BAJANDO POR ESCALERAS, SE LE CAE AGUA SOBRE EL PIE IZQ | G25: si | P25: x | Q25: x
A26: CALVO LUCAS EZEQUIEL | B26: chapa | C26: 29/09/2023 | D26: 04/10/2023 | E26: 6 | F26: REFIERE QUE, AL LEVANTAR UNA OLLA CON UN COMPAÑERO Y AL BAJARLA SIENTE PUNZANTE EN REGION LUMBAR LADO IZQ. | G26: si | P26: x | Q26: x
A27: CRUZ NADIA ANAHI BELEN | B27: represa | C27: 02/10/2023 | D27: 17/10/2023 | E27: 15 | F27: REF QUE ESTABA HACIENDO ENSALADAS, QUISO LEVANTAR UNA FUENTE CON ENSALADA RUSA, ERA MUY PESADA Y SINTIO UN TIRON EN LA ESPALDA. | G27: si | Q27: x
A28: MONDACA CELESTE ROCIO DEL CIELO | B28: bahi blanca | C28: 09/10/2023 | D28: 11/10/2023 | E28: 2 | F28: REF QUE ESTABA LAVANDO CUBIERTO Y SE PINCHO EL DEDO INDICE DE LA MANO DERECHA CON UN CUBIERTO, REF NO PUEDE MOVER LA MANO Y TIENE INFLAMACION EN EL DEDO. | G28: si
A29: VEGA EDUARDO ROBERTO | B29: santa cruz | C29: 11/10/2023 | D29: 25/10/2023 | E29: 45 | F29: REFIERE QUE, LEVANTADO BOLSA DE 25 KG DE HARINA AL LEVANTAR GIRA PARA POSICIONARLA Y SIENTE DOLOR PUNZANTE EN REGION LUMBAR HASTA LA PIERNA IZQ. | G29: si
A30: CRUZ MATIAS NAHUEL | B30: ricon | C30: 45287 | D30: 03/01/2024 | E30: 7 | F30: CORTANDO VERDURAS Y SIENTE UA DISTENSION EN LA MANO DERECHA | G30: si
A31: GONZALEZ FEDERICO | B31: comirsa | C31: 16/11/2023 | D31: 45252 | E31: 7 | F31: LUMBAGO NO ESPECIFICADO | G31: si
A32: AVELLANEDA HECTOR ANIBAL | B32: POBA | C32: 23/12/2023 | D32: 02/01/2024 | E32: 11 | F32: RESBALA Y CAE. PRESENTA GOLPE EN ESPALDA Y CUELLO | G32: si
A33: VEGA EDUARDO ROBERTO | C33: 11/10/2023 | D33: 15/12/2023 | E33: 2 | F33: LUMBALGIA CON CIATICA | G33: si
A34: GUZMAN ANGEL LEONARDO | B34: rincon | C34: 30/11/2023 | D34: 07/12/2023 | E34: 6 | F34: CAE GOLPEANDOSE PIERNA IZQUIERDA | G34: si
A35: ALBORNOZ CARLOS MIGUEL ANGEL | B35: comirsa | C35: 22/11/2023 | D35: 01/12/2023 | E35: 10 | F35: SE QUEMA EN ANTEBRAZO DERECHO SACANDO UNA PLACA DEL HORNO | G35: si
G61: NO | AC61: 3 | AD61: 18
G63: no | AE63: 0 | AF63: 0 | AG63: 0
G65: no | AF65: 1
G66: no | AF66: 1
G67: no | AF67: 3
G69: no | AG69: 1
...

Sheet Casos 2024
A2: Apellido y Nombre | B2: operacion | C2: Accidente | D2: Fin ILT | E2: Dias Acc | F2: Tipo de accidente | G2: Informe de ART | H2: Cumputa? | I2: ene-24 | J2: feb-24 | K2: mar-24 | L2: abr-24 | M2: may-24 | N2: jun-24 | O2: jul-24 | P2: ago-24 | Q2: sep-24 | R2: oct-24 | S2: nov-24 | T2: dic-24
A3: SCHVARZER LUCIANA PAULA | B3: POBA | C3: 45292 | D3: 45301 | E3: 10 | F3: REFIERE QUE ESTABA LLEVANDO EL CARRO CON LAS BANDEJAS CUANDO HACE FUERZA PARA EMPUJARLO SIENTE DOLOR EN EL PIE DERECHO Y DOLOR EN PIERNA IZQ | G3: https://www.provinciart.com.ar/siniestro/3529843 | H3: si | I3: X
A4: PALAVECINO LUCIANA SOLANGE | B4: Rincon | C4: 45294 | D4: 45358 | E4: 5 | F4: REF. QUE CONTINUA CON DOLOR EN PIERNA IZQ DE LA RODILLA HACIA ABAJO C/ HEMATOMA EN LA CANILLA | G4: https://www.provinciart.com.ar/siniestro/3562810 | H4: si | I4: X | J4: X | K4: X
A5: ALDECOA GASPAR SANTIAGO | B5: Chapa | C5: 45300 | D5: 45302 | E5: 3 | F5: REFIERE QUE AL ABRIR UN BIDON QUE CREIA QUE ERA LAVANDINA , AL ASPIRAR EL VAPOR, LE AGARRA MAREOS, NAUSEAS Y TOS | G5: https://www.provinciart.com.ar/siniestro/3533418 | H5: si | I5: X
A6: VALDEZ ANTONELA NOELIA | B6: Rincon | C6: 45313 | D6: 45315 | E6: 2 | F6: REFIERE QUE LAVANDO TACHOS GRANDES Y CAMBROS AL LEVANTARLOS CONTINUAMENTE REF QUE LE TIRA EL HOMBRO DERECHO Y EL CUELLO DEL LADO DERECHO | G6: https://www.provinciart.com.ar/siniestro/3540695 | H6: si | J6: X
A7: LOPEZ ELENA MARIA DEL CARMEN | B7: San Luis | C7: 45318 | D7: 45324 | E7: 6 | F7: REFIERE QUE BAJANDO BANDEJAS HABIA UN VASO ROTO Y SE CORTA CON EL MISMO, DEDO MAYOR D EMANO DERECHA | G7: https://www.provinciart.com.ar/siniestro/3542418 | H7: si | I7: X | J7: X
A8: CEJAS MAXIMILIANO EXEQUIEL | B8: Chapa | C8: 45341 | D8: 45344 | E8: 4 | F8: REF. COMENZO A PRESENTAR DOLOR EN CODO Y MANO DE LADO DERECHO | G8: https://www.provinciart.com.ar/siniestro/3552251 | H8: si | J8: X
A9: VERA ROMINA ELIZABETH | B9: Rincon | C9: 45344 | D9: 45364 | E9: 21 | F9: REFIERE QUE ESTABA HACIENDO UNA LIMPIEZA GENERAL, AGARRA EL BALDE DE AGUA CALIENTE, SE LE RESBALA Y LE CAE EN EL PIE IZQUIERDO QUEMÁNDOSE. | G9: https://www.provinciart.com.ar/siniestro/3554851 | H9: si | J9: X | K9: X
A10: CALVO PARRA MANUEL | B10: UBA | C10: 45369 | D10: 45376 | E10: 8 | F10: REFIERE QUE ESTABA ARMANDO UN CAFE Y SE CHORREO LECHE HERVIDA EN DEDO MEDIO, INDICE Y ANULAR MANO IZQUIERDA. | G10: https://www.provinciart.com.ar/siniestro/3570566 | H10: si | K10: X
A11: MENDEZ EVELYN MELISA | B11: Rincon | C11: 45372 | D11: 45385 | E11: 14 | F11: REF QUE ESTABA SACANDO LAS PAPAS DEL PELA PAPA, HABIA CASCARAS EN EL PISO, SE RESBALO AL VACIAR EL CANASTO EN LA BACHA, REF GOLPE EN LA MANO DERECHA, CAYO DE COLA, REF GOLPE EN CINTURA Y ESPALDA. | G11: https://www.provinciart.com.ar/siniestro/3572740 | H11: si | K11: X | L11: X
A12: ACEVEDO JUAN JOSE | B12: Añelo | C12: 45386 | D12: 45404 | E12: 18 | F12: EL TRABAJADOR SE ENCONTRABA MANEJANDO CUANDO UN ANIMAL SE CRUZÓ EN EL CAMINO Y EMBISTIÓ EL VEHICULO. | G12: https://www.provinciart.com.ar/siniestro/3579329 | H12: si | L12: X
A13: SOSA JORGE EMANUEL | B13: CABA | C13: 45483 | D13: 45488 | E13: 5 | F13: YENDO DE VILLA MARIA A SAN LUIS EN LA CAMIONETA DE LA EMPRESA, CON OTRO EMPLEADO, LOS CHOCA DE ATRAS UN CAMION, LATIGO CERVICAL | G13: https://www.provinciart.com.ar/siniestro/3634336 | H13: si | O13: X
A14: BAREIRO DIEGO FERNANDO | B14: CABA | C14: 45483 | D14: 45488 | E14: 5 | F14: YENDO DE VILLA MARIA A SAN LUIS EN LA CAMIONETA DE LA EMPRESA, CON OTRO EMPLEADO, LOS CHOCA DE ATRAS UN CAMION, LATIGO CERVICAL | G14: https://www.provinciart.com.ar/siniestro/3634323 | H14: si | O14: X
A15: GALLARDO JESUS AUGUSTO | B15: Salta | C15: 45490 | D15: 45499 | E15: 9 | F15: REFIERE QUE ESTABA LLEVANDO COMIDA EN LA CAMIONETA DE LA EMPRESA, CUANDO VOLVÍA, UN AUTO FRENA DE GOLPE Y ÉL LO CHOCA, SE GOLPEA PIERNA DER | G15: https://www.provinciart.com.ar/siniestro/3638468 | H15: si | O15: X
A16: VALDIVIEZO ELIANA GABRIELA | B16: Salta | C16: 45499 | D16: 45513 | E16: 5 | F16: REFIERE CUANDO CARGABA CONSERVADORAS A LA CAMIONETA DE TRABAJO SIENTE TIRON EN HOMBRO IZQUIERDO | G16: https://www.provinciart.com.ar/siniestro/3644984 | H16: si | O16: X
A17: LOPEZ ERNESTO FABIAN | B17: Añelo | C17: 45511 | D17: 45520 | E17: 10 | F17: REFIERE QUE ESTABA AJUSTANDO UNA MAQUINA PROCESADORA HACE UN MOVIMIENTO PARA AJUSTARLA CORTANDOSE EL DEDO ANULAR DERECHO CONTRA LA CUCHILLA.FUE ASISTIDO | G17: https://www.provinciart.com.ar/siniestro/3651940 | H17: si
A18: TORRES ANGEL ADRIAN | B18: Salta | C18: 45506 | D18: 45513 | E18: 10 | F18: REFIERE DENUNCIANTE QUE SACANDO UNA BANDEJA DEL HORNO, RESBALA HACIA TRAS CAE GOLPEANDO LA CABEZA CONTRA EL SUELO Y PARTE DE LA ESPALDA | G18: https://www.provinciart.com.ar/siniestro/3648921 | H18: si | P18: x
A19: SOSA ACOSTA SEBASTIAN ALEJANDRO ARIEL | B19: POBA | C19: 45508 | D19: 45510 | E19: 2 | F19: REFIERE QUE ESTABA REALIZANDO LIMPIEZA GENERAL CUANDO COMENZO CO MAREOS Y SANGRADO NAZAL. | H19: si | Q19: x
A20: FALABELLA JUAN IGNACIO | B20: Olavarria | C20: 45595 | D20: 45652 | E20: 36 | F20: REFIERE QUE YENDO A TRABAJAR COLOCANDOSE EL BUZO SE SUBE A LA AVERDA Y CAE SOBRE EL BRAZO DERECHO Y SE SACA EL HOMBRO DE LUGAR | G20: https://www.provinciart.com.ar/siniestro/3722177 | H20: si | R20: x | S20: x | T20: x
A23: Total | C23: =SUBTOTAL(103,C3:C22) -> 18 | I23: =SUBTOTAL(103,I3:I22) -> 4 | J23: =SUBTOTAL(103,J3:J22) -> 5 | K23: =SUBTOTAL(103,K3:K22) -> 4 | L23: =SUBTOTAL(103,L3:L22) -> 2 | M23: =SUBTOTAL(103,M3:M22) -> 0 | N23: =SUBTOTAL(103,N3:N22) -> 0 | O23: =SUBTOTAL(103,O3:O22) -> 4 | P23: =SUBTOTAL(103,P3:P22) -> 1 | ... T23: =SUBTOTAL(103,T3:T22) -> 1

Sheet Casos 2025
A2: Apellido y Nombre | B2: operacion | C2: Accidente | D2: Fin ILT | E2: Dias Acc | F2: Tipo de accidente | G2: Informe de ART | H2: Inoforme Maximia | I2: Cumputa? | J2: ene-25 | K2: feb-25 | L2: mar-25 | M2: abr-25 | N2: may-25 | O2: jun-25 | P2: jul-25 | Q2: ago-25 | R2: sep-25 | S2: oct-25 | T2: nov-25 | U2: dic-25
A3: FRANCO KEVIN ESPEJO | B3: salta | C3: 45698 | D3: 45777 | E3: 61 | F3: REF SE ENCONTRABA CARGANDO UNA CONSERVADORA A LA CAMIONETA Y SU COMPAÑERO LO AGARRA MAL, ESTO HACE QUE SE LE VENZA EL LADO DE EL Y SUFRA TIRON EN LA MUÑECA DERECHA. | G3: https://www.provinciart.com.ar/siniestro/3783036 | H3: https://maximiasams.sharepoint.com/sites/SGC/Documentos%20compartidos/Forms/AllItems.aspx?id=%2Fsites%2FSGC%2FDocumentos%20compartidos%2F08%20-%20Operaciones%2F03%20-%20Control%20de%20Calidad%2FRegistros%2FHyS%2FCOCINAS%2FSALTA%20%28Guemes%29%2F2025%2FFR%20109%20Informe%20de%20Investigación%20de%20Accidentes&viewid=6eac0f6e-1073-4a98-99d6-a56bf71e815e | I3: si | L3: x | M3: x
A4: HERRERA SANDRO ABEL | B4: rincon de los sauces | C4: 45754 | D4: 45855 | E4: 102 | F4: REF QUE ESTABA CORTANDO FIAMBRE Y SE CORTA EL DEDO MEÑIQUE DE LA MANO IZQ | G4: https://www.provinciart.com.ar/siniestro/3795763 | I4: si | M4: x | N4: x
A5: MARTINEZ THOMAS IGNACIO | B5: rincon de los sauces | C5: 45757 | D5: 45761 | E5: 4 | F5: REFIERE QUE ESTABA ARMNADO UNA MINIPIER Y SE CORTO CON LAS CUCHILLAS EN DEDO ANULAR DERECHO. | G5: https://www.provinciart.com.ar/siniestro/3798551 | H5: https://maximiasams.sharepoint.com/sites/SGC/Documentos%20compartidos/Forms/AllItems.aspx?id=%2Fsites%2FSGC%2FDocumentos%20compartidos%2F08%20-%20Operaciones%2F03%20-%20Control%20de%20Calidad%2FRegistros%2FHyS%2FCOCINAS%2FPLANTA%20DE%20ARENA%2F2025%2FFR%20109-01%20Informe%20Técnico%20de%20Investigación%20de%20Accidentes%20e%20Incidentes&viewid=6eac0f6e-1073-4a98-99d6-a56bf71e815e | I5: si | N5: x
A6: ESPINDOLA RAUL OSCAR | B6: POBA | C6: 45857 | D6: 25/07/2025 | E6: 5 | F6: REFIERE QUE SE ENCONTRABA CARGANDO BIDONES DE LAVANDINA CUANDO AL AGARRAR UNO QUE SE ENCONTRABA ABIERTO LE SALPICA EN EN EL OJO IZQ,REFIERE DOLOR Y ARDOR. | G6: https://www.provinciart.com.ar/siniestro/3863138 | I6: si | P6: x
A7: DOMINGUEZ MONICA GRACIELA | B7: CABA | C7: 45873 | D7: 07/08/2025 | E7: 3 | F7: SE LASTIMO EL PIE IZQUIERDO CON UNA MACETA QUE SE CAYO AL MOMENTO DE REALIZAR LAS TAREAS DE LIMPIEZA RUTINARIAS | G7: https://www.provinciart.com.ar/siniestro/3871826 | I7: si | P7: x
A8: AVELLANEDA IRENE BEATRIZ | B8: POBA | C8: 45862 | D8: 45866 | E8: 4 | F8: REF QUE ESTABA SIRVIENDO LA MERIENDA Y SE LE CAE SOBRE EL BRAZO LECHE CALIENTE | G8: https://www.provinciart.com.ar/siniestro/3866177 | I8: si | P8: x
A9: EBENAU EDGAR EMANUEL | B9: PK 327 | C9: 45904 | D9: 45925 | E9: 21 | F9: REFIERE SE CORTA DEDO MENIQUE Y ANULAR IZQUIERDO POR CUCHILLO EN SU TRABAJO | G9: https://www.provinciart.com.ar/siniestro/3894739 | H9: https://maximiasams.sharepoint.com/sites/SGC/Documentos%20compartidos/Forms/AllItems.aspx?id=%2Fsites%2FSGC%2FDocumentos%20compartidos%2F08%20-%20Operaciones%2F03%20-%20Control%20de%20Calidad%2FRegistros%2FHyS%2FCOCINAS%2FPK%20327%2F2025%2FFR%20107%20Control%20de%20Higiene%20y%20Seguridad%2FFR%20109%20Accidentes&viewid=6eac0f6e-1073-4a98-99d6-a56bf71e815e | I9: si | R9: x
A10: ORELLANA DIEGO MIGUEL | B10: RDA | C10: 45989 | D10: 46049 | E10: 61 | F10: REF SE ENCONTRABA LIMPIANDO UN EXTRACTOR, Y ESTE ESTABA ENCENDIDO Y ROZA UNA HELICE Y SE PRODUCE CORTE EN EL DEDO ANULAR Y MEDIO DE MANO DERECHA. | G10: https://www.provinciart.com.ar/siniestro/3952873 | I10: si | T10: x
A11: BULLONES LAURA ALEJANDRA | B11: PK 327 | C11: 22/11/2025 | D11: 45987 | E11: 6 | F11: REFIERE QUE BAJANDO LA ESCALERA DE UN DEPARTAMENTO EN EL COMPLEJO QUE LE PROVEE LA EMPRESA PARA DIRIGIRSE A SU FUNCION LABORAL SE RESBALA Y CAE TX LUMBAR | G11: https://www.provinciart.com.ar/siniestro/3948922 | I11: si | T11: x
A12: SEPULVEDA JOSE EDUARDO | B12: PK 327 | C12: 46013 | D12: 46015 | E12: 10 | F12: REFIERE QUE, TIRANDO RESIDUOS EN CONTEDEDOR DE HIERRO, SE RESBALA Y GOLPEA ESAPALDA LADO DERECHO (A NIVEL RENAL) CONTRA EL CONTENEDOR. PRESENTA DOLOR EN LA REGIÓN Y HEMATOMA | G12: https://www.provinciart.com.ar/siniestro/3962384 | U12: x
A23: Total | C23: =SUBTOTAL(103,C4:C22) -> 8 | J23: =SUBTOTAL(103,J3:J22) -> 0 | K23: =SUBTOTAL(103,K3:K22) -> 0 | L23: =SUBTOTAL(103,L3:L22) -> 1 | M23: =SUBTOTAL(103,M4:M22) -> 1 | N23: =SUBTOTAL(103,N4:N22) -> 2 | O23: =SUBTOTAL(103,O3:O22) -> 0 | P23: =SUBTOTAL(103,P3:P22) -> 2 | Q23: =SUBTOTAL(103,Q3:Q22) -> 0 | R23: =SUBTOTAL(103,R3:R22) -> 1 | S23: =SUBTOTAL(103,S3:S22) -> 0 | T23: =SUBTOTAL(103,T3:T22) -> 2 | U23: =SUBTOTAL(103,U3:U22) -> 1

Sheet Casos 2026
A2: Apellido y Nombre | B2: operacion | C2: Accidente | D2: Fin ILT | E2: Dias Acc | F2: Tipo de accidente | G2: Informe de ART | H2: Inoforme Maximia | I2: Cumputa? | J2: ene-25 | K2: feb-25 | L2: mar-25 | M2: abr-25 | N2: may-25 | O2: jun-25 | P2: jul-25 | Q2: ago-25 | R2: sep-25 | S2: oct-25 | T2: nov-25 | U2: dic-25
A8: AVELLANEDA IRENE BEATRIZ | B8: POBA | C8: 45862 | D8: 45866 | E8: 4 | F8: REF QUE ESTABA SIRVIENDO LA MERIENDA Y SE LE CAE SOBRE EL BRAZO LECHE CALIENTE | G8: https://www.provinciart.com.ar/siniestro/3866177 | I8: si | P8: x
A23: Total | C23: =SUBTOTAL(103,C4:C22) -> 0 | J23: =SUBTOTAL(103,J3:J22) -> 0 | K23: =SUBTOTAL(103,K3:K22) -> 0 | L23: =SUBTOTAL(103,L3:L22) -> 0 | M23: =SUBTOTAL(103,M4:M22) -> 0 | N23: =SUBTOTAL(103,N4:N22) -> 0 | O23: =SUBTOTAL(103,O3:O22) -> 0 | P23: =SUBTOTAL(103,P3:P22) -> 0 | Q23: =SUBTOTAL(103,Q3:Q22) -> 0 | R23: =SUBTOTAL(103,R3:R22) -> 0 | S23: =SUBTOTAL(103,S3:S22) -> 0 | T23: =SUBTOTAL(103,T3:T22) -> 0 | U23: =SUBTOTAL(103,U3:U22) -> 0

Sheet Añelo 2026
C1: INFORME DE SINIESTRALIDAD | F1: 2026
A2: Añuelo
C3: Estadísticas de Accidentes | H3: Incorporar a tablero de indicadores | K3: Incorporar a tablero de indicadores
A4: Mes y Año | B4: Personal | C4: Hht | D4: Accidentes | E4: Días Caídos | F4: Indice de I | G4: indice de f | H4: Tasa de frecuencia Acumulado año eventos cada millon de horas (YTD) | I4: Tasa de frecuencia Acumulado año eventos cada mil de horas (YTD) | J4: Promedio Mensual de eventos | K4: Cada cuantos dias se espera un evento
A6: 46023 | B6: 16 | C6: =B6*200 -> 3200 | D6: 0 | E6: 0 | F6: =D6*1000/B6*12 -> 0 | G6: =D6*1000000/C6 -> 0 | H6: =+SUM($D$6:D7)*1000000/SUM($C$6:C7) -> 0 | I6: =+H6/1000 -> 0 | J6: =+AVERAGE($D$6:D7) -> 0 | K6: =+IF(J6=0,"Sin eventos registrados",30/J6) -> Sin eventos registrados
A7: 46054 | C7: =B7*200 -> 0 | D7: 0 | E7: 0 | F7: =D7*1000/B7*12 -> #DIV/0! | G7: =D7*1000000/C7 -> #DIV/0! | H7: =+SUM($D$6:D8)*1000000/SUM($C$6:C8) -> 0 | I7: =+H7/1000 -> 0 | J7: =+AVERAGE($D$6:D8) -> 0 | K7: =+IF(J7=0,"Sin eventos registrados",30/J7) -> Sin eventos registrados
A8: 46082 | C8: =B8*200 -> 0 | D8: 0 | E8: 0 | F8: =D8*1000/B8*12 -> #DIV/0! | G8: =D8*1000000/C8 -> #DIV/0! | H8: =+SUM($D$6:D9)*1000000/SUM($C$6:C9) -> 0 | I8: =+H8/1000 -> 0 | J8: =+AVERAGE($D$6:D9) -> 0 | K8: =+IF(J8=0,"Sin eventos registrados",30/J8) -> Sin eventos registrados
A9: 46113 | C9: =B9*200 -> 0 | D9: 0 | E9: 0 | F9: =D9*1000/B9*12 -> #DIV/0! | G9: =D9*1000000/C9 -> #DIV/0! | H9: =+SUM($D$6:D10)*1000000/SUM($C$6:C10) -> 0 | I9: =+H9/1000 -> 0 | J9: =+AVERAGE($D$6:D10) -> 0 | K9: =+IF(J9=0,"Sin eventos registrados",30/J9) -> Sin eventos registrados
A10: 46143 | C10: =B10*200 -> 0 | D10: 0 | E10: 0 | F10: =D10*1000/B10*12 -> #DIV/0! | G10: =D10*1000000/C10 -> #DIV/0! | H10: =+SUM($D$6:D11)*1000000/SUM($C$6:C11) -> 0 | I10: =+H10/1000 -> 0 | J10: =+AVERAGE($D$6:D11) -> 0 | K10: =+IF(J10=0,"Sin eventos registrados",30/J10) -> Sin eventos registrados
A11: 46174 | C11: =B11*200 -> 0 | D11: 0 | E11: 0 | F11: =D11*1000/B11*12 -> #DIV/0! | G11: =D11*1000000/C11 -> #DIV/0! | H11: =+SUM($D$6:D12)*1000000/SUM($C$6:C12) -> 0 | I11: =+H11/1000 -> 0 | J11: =+AVERAGE($D$6:D12) -> 0 | K11: =+IF(J11=0,"Sin eventos registrados",30/J11) -> Sin eventos registrados
A12: 46204 | C12: =B12*200 -> 0 | D12: 0 | E12: 0 | F12: =D12*1000/B12 -> #DIV/0! | G12: =D12*1000000/C12 -> #DIV/0! | H12: =+SUM($D$6:D13)*1000000/SUM($C$6:C13) -> 0 | I12: =+H12/1000 -> 0 | J12: =+AVERAGE($D$6:D13) -> 0 | K12: =+IF(J12=0,"Sin eventos registrados",30/J12) -> Sin eventos registrados
A13: 46235 | C13: =B13*200 -> 0 | D13: 0 | E13: 0 | F13: =D13*1000/B13*12 -> #DIV/0! | G13: =D13*1000000/C13 -> #DIV/0! | H13: =+SUM($D$6:D14)*1000000/SUM($C$6:C14) -> 0 | I13: =+H13/1000 -> 0 | J13: =+AVERAGE($D$6:D14) -> 0 | K13: =+IF(J13=0,"Sin eventos registrados",30/J13) -> Sin eventos registrados
A14: 46266 | C14: =B14*200 -> 0 | D14: 0 | E14: 0 | F14: =D14*1000/B14*12 -> #DIV/0! | G14: =D14*1000000/C14 -> #DIV/0! | H14: =+SUM($D$6:D15)*1000000/SUM($C$6:C15) -> 0 | I14: =+H14/1000 -> 0 | J14: =+AVERAGE($D$6:D15) -> 0 | K14: =+IF(J14=0,"Sin eventos registrados",30/J14) -> Sin eventos registrados
A15: 46296 | C15: =B15*200 -> 0 | D15: 0 | E15: 0 | F15: =D15*1000/B15*12 -> #DIV/0! | G15: =D15*1000000/C15 -> #DIV/0! | H15: =+SUM($D$6:D16)*1000000/SUM($C$6:C16) -> 0 | I15: =+H15/1000 -> 0 | J15: =+AVERAGE($D$6:D16) -> 0 | K15: =+IF(J15=0,"Sin eventos registrados",30/J15) -> Sin eventos registrados
A16: 46327 | C16: =B16*200 -> 0 | D16: 0 | E16: 0 | F16: =D16*1000/B16*12 -> #DIV/0! | G16: =D16*1000000/C16 -> #DIV/0! | H16: =+SUM($D$6:D17)*1000000/SUM($C$6:C17) -> 0 | I16: =+H16/1000 -> 0 | J16: =+AVERAGE($D$6:D17) -> 0 | K16: =+IF(J16=0,"Sin eventos registrados",30/J16) -> Sin eventos registrados
A17: 46357 | C17: =B17*200 -> 0 | D17: 0 | E17: 0 | F17: =D17*1000/B17*12 -> #DIV/0! | G17: =D17*1000000/C17 -> #DIV/0! | H17: =+SUM($D$6:D18)*1000000/SUM($C$6:C18) -> 0 | I17: =+H17/1000 -> 0 | J17: =+AVERAGE($D$6:D18) -> 0 | K17: =+IF(J17=0,"Sin eventos registrados",30/J17) -> Sin eventos registrados
A19: Total/Prom | B19: =SUM(B6:B17)/12 -> 1.3333333 | C19: =SUM(C6:C17) -> 3200 | D19: =SUM(D6:D17) -> 0 | E19: =SUM(E6:E17) -> 0 | F19: =D19*1000/B19 -> 0
A22: Indice de Incidencia = | C22: Trab Siniest x 1.000 | D22: = | E22: =D19*1000/B19 -> 0 | F22: Trabajadores siniestrados por cada 1.000 trabajadores.
C23: Trabajadores exp
A25: Indice de Frecuencia = | C25: Trab Siniest x 1.000.000 | D25: = | E25: =D19*1000000/C19 -> 0 | F25: Trabajadores siniestrados por cada 1.000.000 de hs. trabajadas.
C26: Horas Trabajadas
A28: Indice de Gravedad = | C28: Días Caídos | D28: = | E28: =E19/B19 -> 0 | F28: Cantidad de días no trabajados por acc., por cada trabajador.
A29: (pérdida) | C29: Trabajadores exp
A31: El cálculo del Indice de Incidencia contempla la modificación impuesta por la Res 475/11 Superintendencia de Riesgos de Trabajo:
F58: Lic. Vidal Fernando

Sheet Bahia Blanca (2)
C1: INFORME DE SINIESTRALIDAD | F1: 2026
A2: Bahia Blanca
C3: Estadísticas de Accidentes | H3: Incorporar a tablero de indicadores | K3: Incorporar a tablero de indicadores
A4: Mes y Año | B4: Personal | C4: Hht | D4: Accidentes | E4: Días Caídos | F4: Indice de I | G4: indice de f | H4: Tasa de frecuencia Acumulado año eventos cada millon de horas (YTD) | I4: Tasa de frecuencia Acumulado año eventos cada mil de horas (YTD) | J4: Promedio Mensual de eventos | K4: Cada cuantos dias se espera un evento
A6: 46023 | B6: 5 | C6: =B6*8*22 -> 880 | D6: 0 | E6: 0 | F6: =D6*1000/B6*12 -> 0 | G6: =D6*1000000/C6 -> 0 | H6: =+SUM($D$6:D7)*1000000/SUM($C$6:C7) -> 0 | I6: =+H6/1000 -> 0 | J6: =+AVERAGE($D$6:D7) -> 0 | K6: =+IF(J6=0,"Sin eventos registrados",30/J6) -> Sin eventos registrados
A7: 46054 | C7: =B7*8*22 -> 0 | D7: 0 | E7: 0 | F7: =D7*1000/B7*12 -> #DIV/0! | G7: =D7*1000000/C7 -> #DIV/0! | H7: =+SUM($D$6:D8)*1000000/SUM($C$6:C8) -> 0 | I7: =+H7/1000 -> 0 | J7: =+AVERAGE($D$6:D8) -> 0 | K7: =+IF(J7=0,"Sin eventos registrados",30/J7) -> Sin eventos registrados
A8: 46082 | C8: =B8*8*22 -> 0 | D8: 0 | E8: 0 | F8: =D8*1000/B8*12 -> #DIV/0! | G8: =D8*1000000/C8 -> #DIV/0! | H8: =+SUM($D$6:D9)*1000000/SUM($C$6:C9) -> 0 | I8: =+H8/1000 -> 0 | J8: =+AVERAGE($D$6:D9) -> 0 | K8: =+IF(J8=0,"Sin eventos registrados",30/J8) -> Sin eventos registrados
A9: 46113 | C9: =B9*8*22 -> 0 | D9: 0 | E9: 0 | F9: =D9*1000/B9*12 -> #DIV/0! | G9: =D9*1000000/C9 -> #DIV/0! | H9: =+SUM($D$6:D10)*1000000/SUM($C$6:C10) -> 0 | I9: =+H9/1000 -> 0 | J9: =+AVERAGE($D$6:D10) -> 0 | K9: =+IF(J9=0,"Sin eventos registrados",30/J9) -> Sin eventos registrados
A10: 46143 | C10: =B10*200 -> 0 | D10: 0 | E10: 0 | F10: =D10*1000/B10*12 -> #DIV/0! | G10: =D10*1000000/C10 -> #DIV/0! | H10: =+SUM($D$6:D11)*1000000/SUM($C$6:C11) -> 0 | I10: =+H10/1000 -> 0 | J10: =+AVERAGE($D$6:D11) -> 0 | K10: =+IF(J10=0,"Sin eventos registrados",30/J10) -> Sin eventos registrados
A11: 46174 | C11: =B11*200 -> 0 | D11: 0 | E11: 0 | F11: =D11*1000/B11*12 -> #DIV/0! | G11: =D11*1000000/C11 -> #DIV/0! | H11: =+SUM($D$6:D12)*1000000/SUM($C$6:C12) -> 0 | I11: =+H11/1000 -> 0 | J11: =+AVERAGE($D$6:D12) -> 0 | K11: =+IF(J11=0,"Sin eventos registrados",30/J11) -> Sin eventos registrados
A12: 46204 | C12: =B12*200 -> 0 | D12: 0 | E12: 0 | F12: =D12*1000/B12 -> #DIV/0! | G12: =D12*1000000/C12 -> #DIV/0! | H12: =+SUM($D$6:D13)*1000000/SUM($C$6:C13) -> 0 | I12: =+H12/1000 -> 0 | J12: =+AVERAGE($D$6:D13) -> 0 | K12: =+IF(J12=0,"Sin eventos registrados",30/J12) -> Sin eventos registrados
A13: 46235 | C13: =B13*8*22 -> 0 | D13: 0 | E13: 0 | F13: =D13*1000/B13*12 -> #DIV/0! | G13: =D13*1000000/C13 -> #DIV/0! | H13: =+SUM($D$6:D14)*1000000/SUM($C$6:C14) -> 0 | I13: =+H13/1000 -> 0 | J13: =+AVERAGE($D$6:D14) -> 0 | K13: =+IF(J13=0,"Sin eventos registrados",30/J13) -> Sin eventos registrados
A14: 46266 | C14: =B14*8*22 -> 0 | D14: 0 | E14: 0 | F14: =D14*1000/B14*12 -> #DIV/0! | G14: =D14*1000000/C14 -> #DIV/0! | H14: =+SUM($D$6:D15)*1000000/SUM($C$6:C15) -> 0 | I14: =+H14/1000 -> 0 | J14: =+AVERAGE($D$6:D15) -> 0 | K14: =+IF(J14=0,"Sin eventos registrados",30/J14) -> Sin eventos registrados
A15: 46296 | C15: =B15*8*22 -> 0 | D15: 0 | E15: 0 | F15: =D15*1000/B15*12 -> #DIV/0! | G15: =D15*1000000/C15 -> #DIV/0! | H15: =+SUM($D$6:D16)*1000000/SUM($C$6:C16) -> 0 | I15: =+H15/1000 -> 0 | J15: =+AVERAGE($D$6:D16) -> 0 | K15: =+IF(J15=0,"Sin eventos registrados",30/J15) -> Sin eventos registrados
A16: 46327 | C16: =B16*8*22 -> 0 | D16: 0 | E16: 0 | F16: =D16*1000/B16*12 -> #DIV/0! | G16: =D16*1000000/C16 -> #DIV/0! | H16: =+SUM($D$6:D17)*1000000/SUM($C$6:C17) -> 0 | I16: =+H16/1000 -> 0 | J16: =+AVERAGE($D$6:D17) -> 0 | K16: =+IF(J16=0,"Sin eventos registrados",30/J16) -> Sin eventos registrados
A17: 46357 | C17: =B17*8*22 -> 0 | D17: 0 | E17: 0 | F17: =D17*1000/B17*12 -> #DIV/0! | G17: =D17*1000000/C17 -> #DIV/0! | H17: =+SUM($D$6:D18)*1000000/SUM($C$6:C18) -> 0 | I17: =+H17/1000 -> 0 | J17: =+AVERAGE($D$6:D18) -> 0 | K17: =+IF(J17=0,"Sin eventos registrados",30/J17) -> Sin eventos registrados
A19: Total/Prom | B19: =SUM(B6:B17)/12 -> 0.41666667 | C19: =SUM(C6:C17) -> 880 | D19: =SUM(D6:D17) -> 0 | E19: =SUM(E6:E17) -> 0 | F19: =D19*1000/B19 -> 0
A22: Indice de Incidencia = | C22: Trab Siniest x 1.000 | D22: = | E22: =D19*1000/B19 -> 0 | F22: Trabajadores siniestrados por cada 1.000 trabajadores.
C23: Trabajadores exp
A25: Indice de Frecuencia = | C25: Trab Siniest x 1.000.000 | D25: = | E25: =D19*1000000/C19 -> 0 | F25: Trabajadores siniestrados por cada 1.000.000 de hs. trabajadas.
C26: Horas Trabajadas
A28: Indice de Gravedad = | C28: Días Caídos | D28: = | E28: =E19/B19 -> 0 | F28: Cantidad de días no trabajados por acc., por cada trabajador.
A29: (pérdida) | C29: Trabajadores exp
A31: El cálculo del Indice de Incidencia contempla la modificación impuesta por la Res 475/11 Superintendencia de Riesgos de Trabajo:
F58: Lic. Vidal Fernando

Sheet Casa Central (2)
C1: INFORME DE SINIESTRALIDAD | F1: 2026
A2: Casa Central
C3: Estadísticas de Accidentes | H3: Incorporar a tablero de indicadores | K3: Incorporar a tablero de indicadores
A4: Mes y Año | B4: Personal | C4: Hht | D4: Accidentes | E4: Días Caídos | F4: Indice de I | G4: indice de f | H4: Tasa de frecuencia Acumulado año eventos cada millon de horas (YTD) | I4: Tasa de frecuencia Acumulado año eventos cada mil de horas (YTD) | J4: Promedio Mensual de eventos | K4: Cada cuantos dias se espera un evento
A6: 46023 | B6: 5 | C6: =B6*200 -> 1000 | D6: 0 | E6: 0 | F6: =D6*1000/B6*12 -> 0 | G6: =D6*1000000/C6 -> 0 | H6: =+D7*1000000/C7 -> #DIV/0! | I6: =+H6/1000 -> #DIV/0! | J6: =+AVERAGE($D$6:D7) -> 0 | K6: =+IF(J6=0,"Sin eventos registrados",30/J6) -> Sin eventos registrados
A7: 46054 | C7: =B7*200 -> 0 | D7: 0 | E7: 0 | F7: =D7*1000/B7*12 -> #DIV/0! | G7: =D7*1000000/C7 -> #DIV/0! | H7: =+SUM($D$6:D8)*1000000/SUM($C$6:C8) -> 0 | I7: =+H7/1000 -> 0 | J7: =+AVERAGE($D$6:D8) -> 0 | K7: =+IF(J7=0,"Sin eventos registrados",30/J7) -> Sin eventos registrados
A8: 46082 | C8: =B8*200 -> 0 | D8: 0 | E8: 0 | F8: =D8*1000/B8*12 -> #DIV/0! | G8: =D8*1000000/C8 -> #DIV/0! | H8: =+SUM($D$6:D9)*1000000/SUM($C$6:C9) -> 0 | I8: =+H8/1000 -> 0 | J8: =+AVERAGE($D$6:D9) -> 0 | K8: =+IF(J8=0,"Sin eventos registrados",30/J8) -> Sin eventos registrados
A9: 46113 | C9: =B9*200 -> 0 | D9: 0 | E9: 0 | F9: =D9*1000/B9*12 -> #DIV/0! | G9: =D9*1000000/C9 -> #DIV/0! | H9: =+SUM($D$6:D10)*1000000/SUM($C$6:C10) -> 0 | I9: =+H9/1000 -> 0 | J9: =+AVERAGE($D$6:D10) -> 0 | K9: =+IF(J9=0,"Sin eventos registrados",30/J9) -> Sin eventos registrados
A10: 46143 | C10: =B10*200 -> 0 | D10: 0 | E10: 0 | F10: =D10*1000/B10*12 -> #DIV/0! | G10: =D10*1000000/C10 -> #DIV/0! | H10: =+SUM($D$6:D11)*1000000/SUM($C$6:C11) -> 0 | I10: =+H10/1000 -> 0 | J10: =+AVERAGE($D$6:D11) -> 0 | K10: =+IF(J10=0,"Sin eventos registrados",30/J10) -> Sin eventos registrados
A11: 46174 | C11: =B11*200 -> 0 | D11: 0 | E11: 0 | F11: =D11*1000/B11*12 -> #DIV/0! | G11: =D11*1000000/C11 -> #DIV/0! | H11: =+SUM($D$6:D12)*1000000/SUM($C$6:C12) -> 1000 | I11: =+H11/1000 -> 1 | J11: =+AVERAGE($D$6:D12) -> 0.14285714 | K11: =+IF(J11=0,"Sin eventos registrados",30/J11) -> 210
A12: 46204 | C12: =B12*200 -> 0 | D12: 1 | E12: 2 | F12: =D12*1000/B12 -> #DIV/0! | G12: =D12*1000000/C12 -> #DIV/0! | H12: =+SUM($D$6:D13)*1000000/SUM($C$6:C13) -> 1000 | I12: =+H12/1000 -> 1 | J12: =+AVERAGE($D$6:D13) -> 0.125 | K12: =+IF(J12=0,"Sin eventos registrados",30/J12) -> 240
A13: 46235 | C13: =B13*200 -> 0 | D13: 0 | E13: 0 | F13: =D13*1000/B13*12 -> #DIV/0! | G13: =D13*1000000/C13 -> #DIV/0! | H13: =+SUM($D$6:D14)*1000000/SUM($C$6:C14) -> 1000 | I13: =+H13/1000 -> 1 | J13: =+AVERAGE($D$6:D14) -> 0.11111111 | K13: =+IF(J13=0,"Sin eventos registrados",30/J13) -> 270
A14: 46266 | C14: =B14*200 -> 0 | D14: 0 | E14: 0 | F14: =D14*1000/B14*12 -> #DIV/0! | G14: =D14*1000000/C14 -> #DIV/0! | H14: =+SUM($D$6:D15)*1000000/SUM($C$6:C15) -> 1000 | I14: =+H14/1000 -> 1 | J14: =+AVERAGE($D$6:D15) -> 0.1 | K14: =+IF(J14=0,"Sin eventos registrados",30/J14) -> 300
A15: 46296 | C15: =B15*8*22 -> 0 | D15: 0 | E15: 0 | F15: =D15*1000/B15*12 -> #DIV/0! | G15: =D15*1000000/C15 -> #DIV/0! | H15: =+SUM($D$6:D16)*1000000/SUM($C$6:C16) -> 1000 | I15: =+H15/1000 -> 1 | J15: =+AVERAGE($D$6:D16) -> 0.090909091 | K15: =+IF(J15=0,"Sin eventos registrados",30/J15) -> 330
A16: 46327 | C16: =B16*8*22 -> 0 | D16: 0 | E16: 0 | F16: =D16*1000/B16*12 -> #DIV/0! | G16: =D16*1000000/C16 -> #DIV/0! | H16: =+SUM($D$6:D17)*1000000/SUM($C$6:C17) -> 1000 | I16: =+H16/1000 -> 1 | J16: =+AVERAGE($D$6:D17) -> 0.083333333 | K16: =+IF(J16=0,"Sin eventos registrados",30/J16) -> 360
A17: 46357 | C17: =B17*8*22 -> 0 | D17: 0 | E17: 0 | F17: =D17*1000/B17*12 -> #DIV/0! | G17: =D17*1000000/C17 -> #DIV/0! | H17: =+SUM($D$6:D18)*1000000/SUM($C$6:C18) -> 1000 | I17: =+H17/1000 -> 1 | J17: =+AVERAGE($D$6:D18) -> 0.083333333 | K17: =+IF(J17=0,"Sin eventos registrados",30/J17) -> 360
A19: Total/Prom | B19: =SUM(B6:B17)/12 -> 0.41666667 | C19: =SUM(C6:C17) -> 1000 | D19: =SUM(D6:D17) -> 1 | E19: =SUM(E6:E17) -> 2 | F19: =D19*1000/B19 -> 2400
A22: Indice de Incidencia = | C22: Trab Siniest x 1.000 | D22: = | E22: =D19*1000/B19 -> 2400 | F22: Trabajadores siniestrados por cada 1.000 trabajadores.
C23: Trabajadores exp
A25: Indice de Frecuencia = | C25: Trab Siniest x 1.000.000 | D25: = | E25: =D19*1000000/C19 -> 1000 | F25: Trabajadores siniestrados por cada 1.000.000 de hs. trabajadas.
C26: Horas Trabajadas
A28: Indice de Gravedad = | C28: Días Caídos | D28: = | E28: =E19/B19 -> 4.8 | F28: Cantidad de días no trabajados por acc., por cada trabajador.
A29: (pérdida) | C29: Trabajadores exp
A31: El cálculo del Indice de Incidencia contempla la modificación impuesta por la Res 475/11 Superintendencia de Riesgos de Trabajo:
F58: Lic. Vidal Fernando

Sheet Casa Central 2026
C1: INFORME DE SINIESTRALIDAD | F1: 2026
A2: Casa Central
C3: Estadísticas de Accidentes | H3: Incorporar a tablero de indicadores | K3: Incorporar a tablero de indicadores
A4: Mes y Año | B4: Personal | C4: Hht | D4: Accidentes | E4: Días Caídos | F4: Indice de I | G4: indice de f | H4: Tasa de frecuencia Acumulado año eventos cada millon de horas (YTD) | I4: Tasa de frecuencia Acumulado año eventos cada mil de horas (YTD) | J4: Promedio Mensual de eventos | K4: Cada cuantos dias se espera un evento
A6: 46023 | B6: 68 | C6: =B6*200 -> 13600 | D6: 0 | E6: 0 | F6: =D6*1000/B6*12 -> 0 | G6: =D6*1000000/C6 -> 0 | H6: =+SUM($D$6:D7)*1000000/SUM($C$6:C7) -> 0 | I6: =+H6/1000 -> 0 | J6: =+AVERAGE($D$6:D7) -> 0 | K6: =+IF(J6=0,"Sin eventos registrados",30/J6) -> Sin eventos registrados
A7: 46054 | C7: =B7*200 -> 0 | D7: 0 | E7: 0 | F7: =D7*1000/B7*12 -> #DIV/0! | G7: =D7*1000000/C7 -> #DIV/0! | H7: =+SUM($D$6:D8)*1000000/SUM($C$6:C8) -> 0 | I7: =+H7/1000 -> 0 | J7: =+AVERAGE($D$6:D8) -> 0 | K7: =+IF(J7=0,"Sin eventos registrados",30/J7) -> Sin eventos registrados
A8: 46082 | C8: =B8*200 -> 0 | D8: 0 | E8: 0 | F8: =D8*1000/B8*12 -> #DIV/0! | G8: =D8*1000000/C8 -> #DIV/0! | H8: =+SUM($D$6:D9)*1000000/SUM($C$6:C9) -> 0 | I8: =+H8/1000 -> 0 | J8: =+AVERAGE($D$6:D9) -> 0 | K8: =+IF(J8=0,"Sin eventos registrados",30/J8) -> Sin eventos registrados
A9: 46113 | C9: =B9*200 -> 0 | D9: 0 | E9: 0 | F9: =D9*1000/B9*12 -> #DIV/0! | G9: =D9*1000000/C9 -> #DIV/0! | H9: =+SUM($D$6:D10)*1000000/SUM($C$6:C10) -> 0 | I9: =+H9/1000 -> 0 | J9: =+AVERAGE($D$6:D10) -> 0 | K9: =+IF(J9=0,"Sin eventos registrados",30/J9) -> Sin eventos registrados
A10: 46143 | C10: =B10*200 -> 0 | D10: 0 | E10: 0 | F10: =D10*1000/B10*12 -> #DIV/0! | G10: =D10*1000000/C10 -> #DIV/0! | H10: =+SUM($D$6:D11)*1000000/SUM($C$6:C11) -> 0 | I10: =+H10/1000 -> 0 | J10: =+AVERAGE($D$6:D11) -> 0 | K10: =+IF(J10=0,"Sin eventos registrados",30/J10) -> Sin eventos registrados
A11: 46174 | C11: =B11*200 -> 0 | D11: 0 | E11: 0 | F11: =D11*1000/B11*12 -> #DIV/0! | G11: =D11*1000000/C11 -> #DIV/0! | H11: =+SUM($D$6:D12)*1000000/SUM($C$6:C12) -> 0 | I11: =+H11/1000 -> 0 | J11: =+AVERAGE($D$6:D12) -> 0 | K11: =+IF(J11=0,"Sin eventos registrados",30/J11) -> Sin eventos registrados
A12: 46204 | C12: =B12*200 -> 0 | D12: 0 | E12: 0 | F12: =D12*1000/B12 -> #DIV/0! | G12: =D12*1000000/C12 -> #DIV/0! | H12: =+SUM($D$6:D13)*1000000/SUM($C$6:C13) -> 0 | I12: =+H12/1000 -> 0 | J12: =+AVERAGE($D$6:D13) -> 0 | K12: =+IF(J12=0,"Sin eventos registrados",30/J12) -> Sin eventos registrados
A13: 46235 | C13: =B13*200 -> 0 | D13: 0 | E13: 0 | F13: =D13*1000/B13*12 -> #DIV/0! | G13: =D13*1000000/C13 -> #DIV/0! | H13: =+SUM($D$6:D14)*1000000/SUM($C$6:C14) -> 0 | I13: =+H13/1000 -> 0 | J13: =+AVERAGE($D$6:D14) -> 0 | K13: =+IF(J13=0,"Sin eventos registrados",30/J13) -> Sin eventos registrados
A14: 46266 | C14: =B14*200 -> 0 | D14: 0 | E14: 0 | F14: =D14*1000/B14*12 -> #DIV/0! | G14: =D14*1000000/C14 -> #DIV/0! | H14: =+SUM($D$6:D15)*1000000/SUM($C$6:C15) -> 0 | I14: =+H14/1000 -> 0 | J14: =+AVERAGE($D$6:D15) -> 0 | K14: =+IF(J14=0,"Sin eventos registrados",30/J14) -> Sin eventos registrados
A15: 46296 | C15: =B15*8*22 -> 0 | D15: 0 | E15: 0 | F15: =D15*1000/B15*12 -> #DIV/0! | G15: =D15*1000000/C15 -> #DIV/0! | H15: =+SUM($D$6:D16)*1000000/SUM($C$6:C16) -> 0 | I15: =+H15/1000 -> 0 | J15: =+AVERAGE($D$6:D16) -> 0 | K15: =+IF(J15=0,"Sin eventos registrados",30/J15) -> Sin eventos registrados
A16: 46327 | C16: =B16*8*22 -> 0 | D16: 0 | E16: 0 | F16: =D16*1000/B16*12 -> #DIV/0! | G16: =D16*1000000/C16 -> #DIV/0! | H16: =+SUM($D$6:D17)*1000000/SUM($C$6:C17) -> 0 | I16: =+H16/1000 -> 0 | J16: =+AVERAGE($D$6:D17) -> 0 | K16: =+IF(J16=0,"Sin eventos registrados",30/J16) -> Sin eventos registrados
A17: 46357 | C17: =B17*8*22 -> 0 | D17: 0 | E17: 0 | F17: =D17*1000/B17*12 -> #DIV/0! | G17: =D17*1000000/C17 -> #DIV/0! | H17: =+SUM($D$6:D18)*1000000/SUM($C$6:C18) -> 0 | I17: =+H17/1000 -> 0 | J17: =+AVERAGE($D$6:D18) -> 0 | K17: =+IF(J17=0,"Sin eventos registrados",30/J17) -> Sin eventos registrados
A19: Total/Prom | B19: =SUM(B6:B17)/12 -> 5.6666667 | C19: =SUM(C6:C17) -> 13600 | D19: =SUM(D6:D17) -> 0 | E19: =SUM(E6:E17) -> 0 | F19: =D19*1000/B19 -> 0
A22: Indice de Incidencia = | C22: Trab Siniest x 1.000 | D22: = | E22: =D19*1000/B19 -> 0 | F22: Trabajadores siniestrados por cada 1.000 trabajadores.
C23: Trabajadores exp
A25: Indice de Frecuencia = | C25: Trab Siniest x 1.000.000 | D25: = | E25: =D19*1000000/C19 -> 0 | F25: Trabajadores siniestrados por cada 1.000.000 de hs. trabajadas.
C26: Horas Trabajadas
A28: Indice de Gravedad = | C28: Días Caídos | D28: = | E28: =E19/B19 -> 0 | F28: Cantidad de días no trabajados por acc., por cada trabajador.
A29: (pérdida) | C29: Trabajadores exp
A31: El cálculo del Indice de Incidencia contempla la modificación impuesta por la Res 475/11 Superintendencia de Riesgos de Trabajo:
F58: Lic. Vidal Fernando

Sheet AESA (Punta Arena) 2026
C1: INFORME DE SINIESTRALIDAD | F1: 2026
A2: Punta arena
C3: Estadísticas de Accidentes | H3: Incorporar a tablero de indicadores | K3: Incorporar a tablero de indicadores
A4: Mes y Año | B4: Personal | C4: Hht | D4: Accidentes | E4: Días Caídos | F4: Indice de I | G4: indice de f | H4: Tasa de frecuencia Acumulado año eventos cada millon de horas (YTD) | I4: Tasa de frecuencia Acumulado año eventos cada mil de horas (YTD) | J4: Promedio Mensual de eventos | K4: Cada cuantos dias se espera un evento
A6: 46023 | B6: 18 | C6: =B6*200 -> 3600 | D6: 0 | E6: 0 | F6: =D6*1000/B6*12 -> 0 | G6: =D6*1000000/C6 -> 0 | H6: =+SUM($D$6:D7)*1000000/SUM($C$6:C7) -> 0 | I6: =+H6/1000 -> 0 | J6: =+AVERAGE($D$6:D7) -> 0 | K6: =+IF(J6=0,"Sin eventos registrados",30/J6) -> Sin eventos registrados
A7: 46054 | C7: =B7*200 -> 0 | D7: 0 | E7: 0 | F7: =D7*1000/B7*12 -> #DIV/0! | G7: =D7*1000000/C7 -> #DIV/0! | H7: =+SUM($D$6:D8)*1000000/SUM($C$6:C8) -> 0 | I7: =+H7/1000 -> 0 | J7: =+AVERAGE($D$6:D8) -> 0 | K7: =+IF(J7=0,"Sin eventos registrados",30/J7) -> Sin eventos registrados
A8: 46082 | C8: =B8*200 -> 0 | D8: 0 | E8: 0 | F8: =D8*1000/B8*12 -> #DIV/0! | G8: =D8*1000000/C8 -> #DIV/0! | H8: =+SUM($D$6:D9)*1000000/SUM($C$6:C9) -> 0 | I8: =+H8/1000 -> 0 | J8: =+AVERAGE($D$6:D9) -> 0 | K8: =+IF(J8=0,"Sin eventos registrados",30/J8) -> Sin eventos registrados
A9: 46113 | C9: =B9*200 -> 0 | D9: 0 | E9: 0 | F9: =D9*1000/B9*12 -> #DIV/0! | G9: =D9*1000000/C9 -> #DIV/0! | H9: =+SUM($D$6:D10)*1000000/SUM($C$6:C10) -> 0 | I9: =+H9/1000 -> 0 | J9: =+AVERAGE($D$6:D10) -> 0 | K9: =+IF(J9=0,"Sin eventos registrados",30/J9) -> Sin eventos registrados
A10: 46143 | C10: =B10*200 -> 0 | D10: 0 | E10: 0 | F10: =D10*1000/B10*12 -> #DIV/0! | G10: =D10*1000000/C10 -> #DIV/0! | H10: =+SUM($D$6:D11)*1000000/SUM($C$6:C11) -> 0 | I10: =+H10/1000 -> 0 | J10: =+AVERAGE($D$6:D11) -> 0 | K10: =+IF(J10=0,"Sin eventos registrados",30/J10) -> Sin eventos registrados
A11: 46174 | C11: =B11*200 -> 0 | D11: 0 | E11: 0 | F11: =D11*1000/B11 -> #DIV/0! | G11: =D11*1000000/C11 -> #DIV/0! | H11: =+SUM($D$6:D12)*1000000/SUM($C$6:C12) -> 0 | I11: =+H11/1000 -> 0 | J11: =+AVERAGE($D$6:D12) -> 0 | K11: =+IF(J11=0,"Sin eventos registrados",30/J11) -> Sin eventos registrados
A12: 46204 | C12: =B12*200 -> 0 | D12: 0 | E12: 0 | F12: =D12*1000/B12*12 -> #DIV/0! | G12: =D12*1000000/C12 -> #DIV/0! | H12: =+SUM($D$6:D13)*1000000/SUM($C$6:C13) -> 0 | I12: =+H12/1000 -> 0 | J12: =+AVERAGE($D$6:D13) -> 0 | K12: =+IF(J12=0,"Sin eventos registrados",30/J12) -> Sin eventos registrados
A13: 46235 | C13: =B13*200 -> 0 | D13: 0 | E13: 0 | F13: =D13*1000/B13*12 -> #DIV/0! | G13: =D13*1000000/C13 -> #DIV/0! | H13: =+SUM($D$6:D14)*1000000/SUM($C$6:C14) -> 0 | I13: =+H13/1000 -> 0 | J13: =+AVERAGE($D$6:D14) -> 0 | K13: =+IF(J13=0,"Sin eventos registrados",30/J13) -> Sin eventos registrados
A14: 46266 | C14: =B14*8*22 -> 0 | D14: 0 | E14: 0 | F14: =D14*1000/B14*12 -> #DIV/0! | G14: =D14*1000000/C14 -> #DIV/0! | H14: =+SUM($D$6:D15)*1000000/SUM($C$6:C15) -> 0 | I14: =+H14/1000 -> 0 | J14: =+AVERAGE($D$6:D15) -> 0 | K14: =+IF(J14=0,"Sin eventos registrados",30/J14) -> Sin eventos registrados
A15: 46296 | C15: =B15*8*22 -> 0 | D15: 0 | E15: 0 | F15: =D15*1000/B15*12 -> #DIV/0! | G15: =D15*1000000/C15 -> #DIV/0! | H15: =+SUM($D$6:D16)*1000000/SUM($C$6:C16) -> 0 | I15: =+H15/1000 -> 0 | J15: =+AVERAGE($D$6:D16) -> 0 | K15: =+IF(J15=0,"Sin eventos registrados",30/J15) -> Sin eventos registrados
A16: 46327 | C16: =B16*8*22 -> 0 | D16: 0 | E16: 0 | F16: =D16*1000/B16*12 -> #DIV/0! | G16: =D16*1000000/C16 -> #DIV/0! | H16: =+SUM($D$6:D17)*1000000/SUM($C$6:C17) -> 0 | I16: =+H16/1000 -> 0 | J16: =+AVERAGE($D$6:D17) -> 0 | K16: =+IF(J16=0,"Sin eventos registrados",30/J16) -> Sin eventos registrados
A17: 46357 | C17: =B17*8*22 -> 0 | D17: 0 | E17: 0 | F17: =D17*1000/B17*12 -> #DIV/0! | G17: =D17*1000000/C17 -> #DIV/0! | H17: =+SUM($D$6:D18)*1000000/SUM($C$6:C18) -> 0 | I17: =+H17/1000 -> 0 | J17: =+AVERAGE($D$6:D18) -> 0 | K17: =+IF(J17=0,"Sin eventos registrados",30/J17) -> Sin eventos registrados
B18: 0
A19: Total/Prom | B19: =SUM(B6:B17)/12 -> 1.5 | C19: =SUM(C6:C17) -> 3600 | D19: =SUM(D6:D17) -> 0 | E19: =SUM(E6:E17) -> 0 | F19: =D19*1000/B19 -> 0
A22: Indice de Incidencia = | C22: Trab Siniest x 1.000 | D22: = | E22: =D19*1000/B19 -> 0 | F22: Trabajadores siniestrados por cada 1.000 trabajadores.
C23: Trabajadores exp
A25: Indice de Frecuencia = | C25: Trab Siniest x 1.000.000 | D25: = | E25: =D19*1000000/C19 -> 0 | F25: Trabajadores siniestrados por cada 1.000.000 de hs. trabajadas.
C26: Horas Trabajadas
A28: Indice de Gravedad = | C28: Días Caídos | D28: = | E28: =E19/B19 -> 0 | F28: Cantidad de días no trabajados por acc., por cada trabajador.
A29: (pérdida) | C29: Trabajadores exp
A31: El cálculo del Indice de Incidencia contempla la modificación impuesta por la Res 475/11 Superintendencia de Riesgos de Trabajo:
E58: Lic. Vidal Fernando

Sheet POBA -25 2026
C1: INFORME DE SINIESTRALIDAD | F1: 2026
A2: Policlinico
C3: Estadísticas de Accidentes | H3: Incorporar a tablero de indicadores | K3: Incorporar a tablero de indicadores
A4: Mes y Año | B4: Personal | C4: Hht | D4: Accidentes | E4: Días Caídos | F4: Indice de I | G4: indice de f | H4: Tasa de frecuencia Acumulado año eventos cada millon de horas (YTD) | I4: Tasa de frecuencia Acumulado año eventos cada mil de horas (YTD) | J4: Promedio Mensual de eventos | K4: Cada cuantos dias se espera un evento
A6: 46023 | B6: 9 | C6: =B6*200 -> 1800 | D6: 0 | E6: 0 | F6: =D6*1000/B6*12 -> 0 | G6: =D6*1000000/C6 -> 0 | H6: =+SUM($D$6:D7)*1000000/SUM($C$6:C7) -> 0 | I6: =+H6/1000 -> 0 | J6: =+AVERAGE($D$6:D7) -> 0 | K6: =+IF(J6=0,"Sin eventos registrados",30/J6) -> Sin eventos registrados
A7: 46054 | C7: =B7*200 -> 0 | D7: 0 | E7: 0 | F7: =D7*1000/B7*12 -> #DIV/0! | G7: =D7*1000000/C7 -> #DIV/0! | H7: =+SUM($D$6:D8)*1000000/SUM($C$6:C8) -> 0 | I7: =+H7/1000 -> 0 | J7: =+AVERAGE($D$6:D8) -> 0 | K7: =+IF(J7=0,"Sin eventos registrados",30/J7) -> Sin eventos registrados
A8: 46082 | C8: =B8*200 -> 0 | D8: 0 | E8: 0 | F8: =D8*1000/B8*12 -> #DIV/0! | G8: =D8*1000000/C8 -> #DIV/0! | H8: =+SUM($D$6:D9)*1000000/SUM($C$6:C9) -> 0 | I8: =+H8/1000 -> 0 | J8: =+AVERAGE($D$6:D9) -> 0 | K8: =+IF(J8=0,"Sin eventos registrados",30/J8) -> Sin eventos registrados
A9: 46113 | C9: =B9*200 -> 0 | D9: 0 | E9: 0 | F9: =D9*1000/B9*12 -> #DIV/0! | G9: =D9*1000000/C9 -> #DIV/0! | H9: =+SUM($D$6:D10)*1000000/SUM($C$6:C10) -> 0 | I9: =+H9/1000 -> 0 | J9: =+AVERAGE($D$6:D10) -> 0 | K9: =+IF(J9=0,"Sin eventos registrados",30/J9) -> Sin eventos registrados
A10: 46143 | C10: =B10*200 -> 0 | D10: 0 | E10: 0 | F10: =D10*1000/B10*12 -> #DIV/0! | G10: =D10*1000000/C10 -> #DIV/0! | H10: =+SUM($D$6:D11)*1000000/SUM($C$6:C11) -> 0 | I10: =+H10/1000 -> 0 | J10: =+AVERAGE($D$6:D11) -> 0 | K10: =+IF(J10=0,"Sin eventos registrados",30/J10) -> Sin eventos registrados
A11: 46174 | C11: =B11*200 -> 0 | D11: 0 | E11: 0 | F11: =D11*1000/B11 -> #DIV/0! | G11: =D11*1000000/C11 -> #DIV/0! | H11: =+SUM($D$6:D12)*1000000/SUM($C$6:C12) -> 0 | I11: =+H11/1000 -> 0 | J11: =+AVERAGE($D$6:D12) -> 0 | K11: =+IF(J11=0,"Sin eventos registrados",30/J11) -> Sin eventos registrados
A12: 46204 | C12: =B12*200 -> 0 | D12: 0 | E12: 0 | F12: =D12*1000/B12*12 -> #DIV/0! | G12: =D12*1000000/C12 -> #DIV/0! | H12: =+SUM($D$6:D13)*1000000/SUM($C$6:C13) -> 0 | I12: =+H12/1000 -> 0 | J12: =+AVERAGE($D$6:D13) -> 0 | K12: =+IF(J12=0,"Sin eventos registrados",30/J12) -> Sin eventos registrados
A13: 46235 | C13: =B13*200 -> 0 | D13: 0 | E13: 0 | F13: =D13*1000/B13*12 -> #DIV/0! | G13: =D13*1000000/C13 -> #DIV/0! | H13: =+SUM($D$6:D14)*1000000/SUM($C$6:C14) -> 0 | I13: =+H13/1000 -> 0 | J13: =+AVERAGE($D$6:D14) -> 0 | K13: =+IF(J13=0,"Sin eventos registrados",30/J13) -> Sin eventos registrados
A14: 46266 | C14: =B14*200 -> 0 | D14: 0 | E14: 0 | F14: =D14*1000/B14*12 -> #DIV/0! | G14: =D14*1000000/C14 -> #DIV/0! | H14: =+SUM($D$6:D15)*1000000/SUM($C$6:C15) -> 0 | I14: =+H14/1000 -> 0 | J14: =+AVERAGE($D$6:D15) -> 0 | K14: =+IF(J14=0,"Sin eventos registrados",30/J14) -> Sin eventos registrados
A15: 46296 | C15: =B15*200 -> 0 | D15: 0 | E15: 0 | F15: =D15*1000/B15*12 -> #DIV/0! | G15: =D15*1000000/C15 -> #DIV/0! | H15: =+SUM($D$6:D16)*1000000/SUM($C$6:C16) -> 0 | I15: =+H15/1000 -> 0 | J15: =+AVERAGE($D$6:D16) -> 0 | K15: =+IF(J15=0,"Sin eventos registrados",30/J15) -> Sin eventos registrados
A16: 46327 | C16: =B16*8*22 -> 0 | D16: 0 | E16: 0 | F16: =D16*1000/B16*12 -> #DIV/0! | G16: =D16*1000000/C16 -> #DIV/0! | H16: =+SUM($D$6:D17)*1000000/SUM($C$6:C17) -> 0 | I16: =+H16/1000 -> 0 | J16: =+AVERAGE($D$6:D17) -> 0 | K16: =+IF(J16=0,"Sin eventos registrados",30/J16) -> Sin eventos registrados
A17: 46357 | C17: =B17*8*22 -> 0 | D17: 0 | E17: 0 | F17: =D17*1000/B17*12 -> #DIV/0! | G17: =D17*1000000/C17 -> #DIV/0! | H17: =+SUM($D$6:D18)*1000000/SUM($C$6:C18) -> 0 | I17: =+H17/1000 -> 0 | J17: =+AVERAGE($D$6:D18) -> 0 | K17: =+IF(J17=0,"Sin eventos registrados",30/J17) -> Sin eventos registrados
B18: 0
A19: Total/Prom | B19: =SUM(B6:B17)/12 -> 0.75 | C19: =SUM(C6:C17) -> 1800 | D19: =SUM(D6:D17) -> 0 | E19: =SUM(E6:E17) -> 0 | F19: =D19*1000/B19 -> 0
A22: Indice de Incidencia = | C22: Trab Siniest x 1.000 | D22: = | E22: =D19*1000/B19 -> 0 | F22: Trabajadores siniestrados por cada 1.000 trabajadores.
C23: Trabajadores exp
A25: Indice de Frecuencia = | C25: Trab Siniest x 1.000.000 | D25: = | E25: =D19*1000000/C19 -> 0 | F25: Trabajadores siniestrados por cada 1.000.000 de hs. trabajadas.
C26: Horas Trabajadas
A28: Indice de Gravedad = | C28: Días Caídos | D28: = | E28: =E19/B19 -> 0 | F28: Cantidad de días no trabajados por acc., por cada trabajador.
A29: (pérdida) | C29: Trabajadores exp
A31: El cálculo del Indice de Incidencia contempla la modificación impuesta por la Res 475/11 Superintendencia de Riesgos de Trabajo:
E58: Lic. Vidal Fernando

Sheet Rincon de Aranda 2026
C1: INFORME DE SINIESTRALIDAD | F1: 2026 | Q1: Accidentes CAUSAS 75% | R1: 39083
A2: Rincon de Aranda
C3: Estadísticas de Accidentes | H3: Incorporar a tablero de indicadores | K3: Incorporar a tablero de indicadores
A4: Mes y Año | B4: Personal | C4: Hht | D4: Accidentes | E4: Días Caídos | F4: Indice de I | G4: indice de f | H4: Tasa de frecuencia Acumulado año eventos cada millon de horas (YTD) | I4: Tasa de frecuencia Acumulado año eventos cada mil de horas (YTD) | J4: Promedio Mensual de eventos | K4: Cada cuantos dias se espera un evento
A6: 46023 | B6: 35 | C6: =B6*200 -> 7000 | D6: 0 | E6: 0 | F6: =D6*1000/B6*12 -> 0 | G6: =D6*1000000/C6 -> 0 | H6: =+SUM($D$6:D7)*1000000/SUM($C$6:C7) -> 0 | I6: =+H6/1000 -> 0 | J6: =+AVERAGE($D$6:D7) -> 0 | K6: =+IF(J6=0,"Sin eventos registrados",30/J6) -> Sin eventos registrados
A7: 46054 | C7: =B7*200 -> 0 | D7: 0 | E7: 0 | F7: =D7*1000/B7*12 -> #DIV/0! | G7: =D7*1000000/C7 -> #DIV/0! | H7: =+SUM($D$6:D8)*1000000/SUM($C$6:C8) -> 0 | I7: =+H7/1000 -> 0 | J7: =+AVERAGE($D$6:D8) -> 0 | K7: =+IF(J7=0,"Sin eventos registrados",30/J7) -> Sin eventos registrados
A8: 46082 | C8: =B8*200 -> 0 | D8: 0 | E8: 0 | F8: =D8*1000/B8*12 -> #DIV/0! | G8: =D8*1000000/C8 -> #DIV/0! | H8: =+SUM($D$6:D9)*1000000/SUM($C$6:C9) -> 0 | I8: =+H8/1000 -> 0 | J8: =+AVERAGE($D$6:D9) -> 0 | K8: =+IF(J8=0,"Sin eventos registrados",30/J8) -> Sin eventos registrados
A9: 46113 | C9: =B9*200 -> 0 | D9: 0 | E9: 0 | F9: =D9*1000/B9*12 -> #DIV/0! | G9: =D9*1000000/C9 -> #DIV/0! | H9: =+SUM($D$6:D10)*1000000/SUM($C$6:C10) -> 0 | I9: =+H9/1000 -> 0 | J9: =+AVERAGE($D$6:D10) -> 0 | K9: =+IF(J9=0,"Sin eventos registrados",30/J9) -> Sin eventos registrados
A10: 46143 | C10: =B10*200 -> 0 | D10: 0 | E10: 0 | F10: =D10*1000/B10*12 -> #DIV/0! | G10: =D10*1000000/C10 -> #DIV/0! | H10: =+SUM($D$6:D11)*1000000/SUM($C$6:C11) -> 0 | I10: =+H10/1000 -> 0 | J10: =+AVERAGE($D$6:D11) -> 0 | K10: =+IF(J10=0,"Sin eventos registrados",30/J10) -> Sin eventos registrados
A11: 46174 | C11: =B11*200 -> 0 | D11: 0 | E11: 0 | F11: =D11*1000/B11 -> #DIV/0! | G11: =D11*1000000/C11 -> #DIV/0! | H11: =+SUM($D$6:D12)*1000000/SUM($C$6:C12) -> 0 | I11: =+H11/1000 -> 0 | J11: =+AVERAGE($D$6:D12) -> 0 | K11: =+IF(J11=0,"Sin eventos registrados",30/J11) -> Sin eventos registrados
A12: 46204 | C12: =B12*200 -> 0 | D12: 0 | E12: 0 | F12: =D12*1000/B12*12 -> #DIV/0! | G12: =D12*1000000/C12 -> #DIV/0! | H12: =+SUM($D$6:D13)*1000000/SUM($C$6:C13) -> 0 | I12: =+H12/1000 -> 0 | J12: =+AVERAGE($D$6:D13) -> 0 | K12: =+IF(J12=0,"Sin eventos registrados",30/J12) -> Sin eventos registrados
A13: 46235 | C13: =B13*200 -> 0 | D13: 0 | E13: 0 | F13: =D13*1000/B13*12 -> #DIV/0! | G13: =D13*1000000/C13 -> #DIV/0! | H13: =+SUM($D$6:D14)*1000000/SUM($C$6:C14) -> 0 | I13: =+H13/1000 -> 0 | J13: =+AVERAGE($D$6:D14) -> 0 | K13: =+IF(J13=0,"Sin eventos registrados",30/J13) -> Sin eventos registrados
A14: 46266 | C14: =B14*200 -> 0 | D14: 0 | E14: 0 | F14: =D14*1000/B14*12 -> #DIV/0! | G14: =D14*1000000/C14 -> #DIV/0! | H14: =+SUM($D$6:D15)*1000000/SUM($C$6:C15) -> 0 | I14: =+H14/1000 -> 0 | J14: =+AVERAGE($D$6:D15) -> 0 | K14: =+IF(J14=0,"Sin eventos registrados",30/J14) -> Sin eventos registrados
A15: 46296 | C15: =B15*200 -> 0 | D15: 0 | E15: 0 | F15: =D15*1000/B15*12 -> #DIV/0! | G15: =D15*1000000/C15 -> #DIV/0! | H15: =+SUM($D$6:D16)*1000000/SUM($C$6:C16) -> 0 | I15: =+H15/1000 -> 0 | J15: =+AVERAGE($D$6:D16) -> 0 | K15: =+IF(J15=0,"Sin eventos registrados",30/J15) -> Sin eventos registrados
A16: 46327 | C16: =B16*200 -> 0 | D16: 0 | E16: 0 | F16: =D16*1000/B16*12 -> #DIV/0! | G16: =D16*1000000/C16 -> #DIV/0! | H16: =+SUM($D$6:D17)*1000000/SUM($C$6:C17) -> 0 | I16: =+H16/1000 -> 0 | J16: =+AVERAGE($D$6:D17) -> 0 | K16: =+IF(J16=0,"Sin eventos registrados",30/J16) -> Sin eventos registrados
A17: 46357 | C17: =B17*200 -> 0 | D17: 0 | E17: 0 | F17: =D17*1000/B17*12 -> #DIV/0! | G17: =D17*1000000/C17 -> #DIV/0! | H17: =+SUM($D$6:D18)*1000000/SUM($C$6:C18) -> 0 | I17: =+H17/1000 -> 0 | J17: =+AVERAGE($D$6:D18) -> 0 | K17: =+IF(J17=0,"Sin eventos registrados",30/J17) -> Sin eventos registrados
A19: Total/Prom | B19: =SUM(B6:B17)/12 -> 2.9166667 | C19: =SUM(C6:C17) -> 7000 | D19: =SUM(D6:D17) -> 0 | E19: =SUM(E6:E17) -> 0 | F19: =D19*1000/B19 -> 0
A22: Indice de Incidencia = | C22: Trab Siniest x 1.000 | D22: = | E22: =D19*1000/B19 -> 0 | F22: Trabajadores siniestrados por cada 1.000 trabajadores.
C23: Trabajadores exp
A25: Indice de Frecuencia = | C25: Trab Siniest x 1.000.000 | D25: = | E25: =D19*1000000/C19 -> 0 | F25: Trabajadores siniestrados por cada 1.000.000 de hs. trabajadas.
C26: Horas Trabajadas
A28: Indice de Gravedad = | C28: Días Caídos | D28: = | E28: =E19/B19 -> 0 | F28: Cantidad de días no trabajados por acc., por cada trabajador.
A29: (pérdida) | C29: Trabajadores exp
A31: El cálculo del Indice de Incidencia contempla la modificación impuesta por la Res 475/11 Superintendencia de Riesgos de Trabajo:
E58: lic. Vidal Fernando

Sheet Ricon de los Sauces 26
C1: INFORME DE SINIESTRALIDAD | F1: 2026
A2: Rincon
C3: Estadísticas de Accidentes | H3: Incorporar a tablero de indicadores | K3: Incorporar a tablero de indicadores
A4: Mes y Año | B4: Personal | C4: Hht | D4: Accidentes | E4: Días Caídos | F4: Indice de I | G4: indice de f | H4: Tasa de frecuencia Acumulado año eventos cada millon de horas (YTD) | I4: Tasa de frecuencia Acumulado año eventos cada mil de horas (YTD) | J4: Promedio Mensual de eventos | K4: Cada cuantos dias se espera un evento
A6: 46023 | B6: 22 | C6: =B6*200 -> 4400 | D6: 0 | E6: 0 | F6: =D6*1000/B6*12 -> 0 | G6: =D6*1000000/C6 -> 0 | H6: =+D7*1000000/C7 -> #DIV/0! | I6: =+H6/1000 -> #DIV/0! | J6: =+AVERAGE($D$6:D7) -> 0 | K6: =+IF(J6=0,"Sin eventos registrados",30/J6) -> Sin eventos registrados
A7: 46054 | C7: =B7*200 -> 0 | D7: 0 | E7: 0 | F7: =D7*1000/B7*12 -> #DIV/0! | G7: =D7*1000000/C7 -> #DIV/0! | H7: =+SUM($D$6:D8)*1000000/SUM($C$6:C8) -> 0 | I7: =+H7/1000 -> 0 | J7: =+AVERAGE($D$6:D8) -> 0 | K7: =+IF(J7=0,"Sin eventos registrados",30/J7) -> Sin eventos registrados
A8: 46082 | C8: =B8*200 -> 0 | D8: 0 | E8: 0 | F8: =D8*1000/B8*12 -> #DIV/0! | G8: =D8*1000000/C8 -> #DIV/0! | H8: =+SUM($D$6:D9)*1000000/SUM($C$6:C9) -> 0 | I8: =+H8/1000 -> 0 | J8: =+AVERAGE($D$6:D9) -> 0 | K8: =+IF(J8=0,"Sin eventos registrados",30/J8) -> Sin eventos registrados
A9: 46113 | C9: =B9*200 -> 0 | D9: 0 | E9: 0 | F9: =D9*1000/B9*12 -> #DIV/0! | G9: =D9*1000000/C9 -> #DIV/0! | H9: =+SUM($D$6:D10)*1000000/SUM($C$6:C10) -> 0 | I9: =+H9/1000 -> 0 | J9: =+AVERAGE($D$6:D10) -> 0 | K9: =+IF(J9=0,"Sin eventos registrados",30/J9) -> Sin eventos registrados
